<?xml version="1.0"?>
<robot name="g_robot" xmlns:xacro="http://www.ros.org/wiki/xacro">
    <material name="black">
        <color rgba="0.0 0.0 0.0 1.0" />
    </material>
    <material name="blue">
        <color rgba="0.203125 0.23828125 0.28515625 1.0" />
    </material>
    <material name="green">
        <color rgba="0.0 0.8 0.0 1.0" />
    </material>
    <material name="grey">
        <color rgba="0.2 0.2 0.2 1.0" />
    </material>
    <material name="orange">
        <color rgba="1.0 0.423529411765 0.0392156862745 1.0" />
    </material>
    <material name="brown">
        <color rgba="0.870588235294 0.811764705882 0.764705882353 1.0" />
    </material>
    <material name="red">
        <color rgba="0.80078125 0.12890625 0.1328125 1.0" />
    </material>
    <material name="white">
        <color rgba="1.0 1.0 1.0 1.0" />
    </material>

    <gazebo reference="link_chassis">
        <material>Gazebo/Orange</material>
    </gazebo>
    <gazebo reference="link_left_wheel">
        <material>Gazebo/Blue</material>
    </gazebo>
    <gazebo reference="link_right_wheel">
        <material>Gazebo/Blue</material>
    </gazebo>
    <!-- <gazebo reference="caster_front_visual">
      <material>Gazebo/Black</material>
  </gazebo> -->

    <!-- TODO: fix drift -->

    <link name="link_chassis">
        <!-- pose and inertial -->
        <pose>0 0 0 0 0 0</pose>
        <inertial>
            <mass value="5" />
            <origin rpy="0 0 0" xyz="0 0 0.1" />
            <inertia ixx="0.159375" ixy="0" ixz="0" iyy="0.159375" iyz="0" izz="0.234375" />
        </inertial>
        <!-- body -->
        <collision name="collision_chassis">
            <origin rpy="0 0 0" xyz="0 0 0.1" />
            <geometry>
                <box size="0.5 0.5 0.3" />  
            </geometry>
        </collision>
        <visual>
            <origin rpy="0 0 0" xyz="0 0 0.1" />
            <geometry>
                <box size="0.5 0.5 0.3" />
            </geometry>
            <material name="blue" />
        </visual>
        <!-- caster front -->
        <collision name="caster_front_collision">
            <origin rpy="0 0 0" xyz="0.175 0 -0.1" />
            <geometry>
                <sphere radius="0.05" />
            </geometry>
            <!-- <surface>
                <friction>
                    <ode>
                        <mu>0</mu>
                        <mu2>0</mu2>
                        <slip1>1.0</slip1>
                        <slip2>1.0</slip2>
                    </ode>
                </friction>
            </surface> -->
        </collision>
        <visual name="caster_front_visual">
            <origin rpy="0 0 0" xyz="0.175 0 -0.1" />
            <geometry>
                <sphere radius="0.05" />
            </geometry>
        </visual>
    </link>

    <link name="link_right_wheel">
        <inertial>
            <mass value="0.2" />
            <origin rpy="0 0 0" xyz="0 0 0" />
            <inertia ixx="0.0008" ixy="0" ixz="0" iyy="0.0015" iyz="0" izz="0.0008" />
        </inertial>
        <collision name="link_right_wheel_collision">
            <origin rpy="0 1.5708 1.5708" xyz="0 0 0" />
            <geometry>
                <cylinder length="0.04" radius="0.125" />
            </geometry>
        </collision>
        <visual name="link_right_wheel_visual">
            <origin rpy="0 1.5708 1.5708" xyz="0 0 0" />
            <geometry>
                <cylinder length="0.04" radius="0.125" />
            </geometry>
        </visual>
    </link>

    <joint name="joint_right_wheel" type="continuous">
        <origin rpy="0 0 0" xyz="-0.1 -0.2 -0.025" />
        <child link="link_right_wheel" />
        <parent link="link_chassis" />
        <axis rpy="0 0 0" xyz="0 1 0" />
        <!-- <limit effort="10000" velocity="1000" />
        <joint_properties damping="1.0" friction="1.0" /> -->
    </joint>

    <link name="link_left_wheel">
        <inertial>
            <mass value="0.2" />
            <origin rpy="0 0 0" xyz="0 0 0" />
            <inertia ixx="0.0008" ixy="0" ixz="0" iyy="0.0015" iyz="0" izz="0.0008" />
        </inertial>
        <collision name="link_left_wheel_collision">
            <origin rpy="0 1.5708 1.5708" xyz="0 0 0" />
            <geometry>
                <cylinder length="0.04" radius="0.125" />
            </geometry>
        </collision>
        <visual name="link_left_wheel_visual">
            <origin rpy="0 1.5708 1.5708" xyz="0 0 0" />
            <geometry>
                <cylinder length="0.04" radius="0.125" />
            </geometry>
        </visual>
    </link>

    <joint name="joint_left_wheel" type="continuous">
        <origin rpy="0 0 0" xyz="-0.1 0.2 -0.025" />
        <child link="link_left_wheel" />
        <parent link="link_chassis" />
        <axis rpy="0 0 0" xyz="0 1 0" />
        <!-- <limit effort="10000" velocity="1000" />
        <joint_properties damping="1.0" friction="1.0" /> -->
    </joint>

</robot>