<?xml version="1.0"?>
<robot name="g_robot" xmlns:xacro="http://www.ros.org/wiki/xacro">
    <material name="black">
        <color rgba="0.0 0.0 0.0 1.0" />
    </material>
    <material name="blue">
        <color rgba="0.203125 0.23828125 0.28515625 1.0" />
    </material>
    <material name="green">
        <color rgba="0.0 0.8 0.0 1.0" />
    </material>
    <material name="grey">
        <color rgba="0.2 0.2 0.2 1.0" />
    </material>
    <material name="orange">
        <color rgba="1.0 0.423529411765 0.0392156862745 1.0" />
    </material>
    <material name="brown">
        <color rgba="0.870588235294 0.811764705882 0.764705882353 1.0" />
    </material>
    <material name="red">
        <color rgba="0.80078125 0.12890625 0.1328125 1.0" />
    </material>
    <material name="white">
        <color rgba="1.0 1.0 1.0 1.0" />
    </material>

    <gazebo reference="chassis_link">
        <material>Gazebo/Orange</material>
    </gazebo>
    <gazebo reference="left_wheel_link">
        <material>Gazebo/Blue</material>
    </gazebo>
    <gazebo reference="right_wheel_link">
        <material>Gazebo/Blue</material>
    </gazebo>
    <gazebo reference="caster_link">
      <material>Gazebo/Black</material>
  </gazebo>

  <gazebo>
      <plugin name="gazebo_ros_control" filename="libgazebo_ros_control.so" />
  </gazebo>

    <!-- TODO: reduce drift -->

    <link name="chassis_link">
        <!-- pose and inertial -->
        <inertial>
            <mass value="10" />
            <origin rpy="0 0 0" xyz="0 0 0.1" />
            <inertia ixx="0.159375" ixy="0" ixz="0" iyy="0.159375" iyz="0" izz="0.234375" />
        </inertial>
        <!-- body -->
        <collision name="collision_chassis">
            <origin rpy="0 0 0" xyz="0 0 0.1" />
            <geometry>
                <box size="0.5 0.5 0.3" />  
            </geometry>
        </collision>
        <visual>
            <origin rpy="0 0 0" xyz="0 0 0.1" />
            <geometry>
                <box size="0.5 0.5 0.3" />
            </geometry>
            <material name="blue" />
        </visual>
    </link>

    <link name="caster_link">
        <inertial>
            <mass value="5" />
            <origin rpy="0 0 0" xyz="0 0 0" />
            <inertia ixx="0.0000382725" ixy="0" ixz="0" iyy="0.0000382725" iyz="0" izz="0.00003815025" />
        </inertial>
        <collision name="caster_collision">
            <origin rpy="0 0 0" xyz="0 0 0" />
            <geometry>
                <sphere radius="0.05" />
            </geometry>
            <surface>
                <friction>
                    <ode>
                        <mu>0</mu>
                        <mu2>0</mu2>
                        <slip1>1.0</slip1>
                        <slip2>1.0</slip2>
                    </ode>
                </friction>
            </surface>
        </collision>
        <visual name="caster_visual">
            <origin rpy="0 0 0" xyz="0 0 0" />
            <geometry>
                <sphere radius="0.05" />
            </geometry>
            <material name="black" />
        </visual>
    </link>

    <joint name="caster_joint" type="fixed">
        <parent link="caster_link" />
        <child link="chassis_link" />
        <origin rpy="0 0 0" xyz="-0.175 0 0.1" />
    </joint>

    <link name="right_wheel_link">
        <inertial>
            <mass value="1" />
            <origin rpy="0 0 0" xyz="0 0 0" />
            <inertia ixx="0.006" ixy="0" ixz="0" iyy="0.01125" iyz="0" izz="0.006" />
        </inertial>
        <collision name="right_wheel_link_collision">
            <origin rpy="0 1.5708 1.5708" xyz="0 0 0" />
            <geometry>
                <cylinder length="0.04" radius="0.125" />
            </geometry>
        </collision>
        <visual name="right_wheel_link_visual">
            <origin rpy="0 1.5708 1.5708" xyz="0 0 0" />
            <geometry>
                <cylinder length="0.04" radius="0.125" />
            </geometry>
        </visual>
    </link>

    <joint name="right_wheel_joint" type="continuous">
        <origin rpy="0 0 0" xyz="-0.1 -0.2 -0.025" />
        <child link="right_wheel_link" />
        <parent link="chassis_link" />
        <axis rpy="0 0 0" xyz="0 1 0" />
        <limit effort="10000" velocity="1000" />
        <joint_properties damping="1.0" friction="1.0" />
    </joint>

    <transmission name="right_wheel_transimssion">
        <type>transmission_interface/SimpleTransmission</type>
        <joint name="right_wheel_joint" >
            <hardwareInterface>hardware_interface/VelocityJointInterface</hardwareInterface>
        </joint>
        <actuator name="right_wheel_actuator">
            <mechanicalReduction>7</mechanicalReduction>
            <hardwareInterface>VelocityJointInterface</hardwareInterface>
        </actuator>
    </transmission>

    <link name="left_wheel_joint">
        <inertial>
            <mass value="1" />
            <origin rpy="0 0 0" xyz="0 0 0" />
            <inertia ixx="0.006" ixy="0" ixz="0" iyy="0.01125" iyz="0" izz="0.006" />
        </inertial>
        <collision name="left_wheel_joint_collision">
            <origin rpy="0 1.5708 1.5708" xyz="0 0 0" />
            <geometry>
                <cylinder length="0.04" radius="0.125" />
            </geometry>
        </collision>
        <visual name="left_wheel_joint_visual">
            <origin rpy="0 1.5708 1.5708" xyz="0 0 0" />
            <geometry>
                <cylinder length="0.04" radius="0.125" />
            </geometry>
        </visual>
    </link>

    <joint name="left_wheel_joint" type="continuous">
        <origin rpy="0 0 0" xyz="-0.1 0.2 -0.025" />
        <child link="left_wheel_joint" />
        <parent link="chassis_link" />
        <axis rpy="0 0 0" xyz="0 1 0" />
        <limit effort="10000" velocity="1000" />
        <joint_properties damping="1.0" friction="1.0" />
    </joint>

    <transmission name="left_wheel_transimssion">
        <type>transmission_interface/SimpleTransmission</type>
        <joint name="left_wheel_joint" >
            <hardwareInterface>hardware_interface/VelocityJointInterface</hardwareInterface>
        </joint>
        <actuator name="left_wheel_actuator">
            <mechanicalReduction>7</mechanicalReduction>
            <hardwareInterface>VelocityJointInterface</hardwareInterface>
        </actuator>
    </transmission>

</robot>